<?xml version="1.0" encoding="utf-8"?>
<!-- This URDF was automatically created by SolidWorks to URDF Exporter! Originally created by Stephen Brawner (brawner@gmail.com) 
     Commit Version: 1.6.0-1-g15f4949  Build Version: 1.6.7594.29634
     For more information, please see http://wiki.ros.org/sw_urdf_exporter -->
<robot
  name="final assembly.SLDASM">
  <link
    name="base_link">
    <inertial>
      <origin
        xyz="0.0013667 -0.0051759 0.59582"
        rpy="0 0 0" />
      <mass
        value="48.317" />
      <inertia
        ixx="0.9334"
        ixy="-0.00020965"
        ixz="0.0031313"
        iyy="1.3776"
        iyz="-0.017266"
        izz="0.60198" />
    </inertial>
    <visual>
      <origin
        xyz="0 0 0"
        rpy="0 0 0" />
      <geometry>
        <mesh
          filename="package://final assembly.SLDASM/meshes/base_link.STL" />
      </geometry>
      <material
        name="">
        <color
          rgba="0.89804 0.91765 0.92941 1" />
      </material>
    </visual>
    <collision>
      <origin
        xyz="0 0 0"
        rpy="0 0 0" />
      <geometry>
        <mesh
          filename="package://final assembly.SLDASM/meshes/base_link.STL" />
      </geometry>
    </collision>
  </link>
  <link
    name="L_Link">
    <inertial>
      <origin
        xyz="-2.7756E-17 0 0"
        rpy="0 0 0" />
      <mass
        value="0.18269" />
      <inertia
        ixx="0.00025245"
        ixy="-4.3584E-37"
        ixz="3.1357E-37"
        iyy="0.00013662"
        iyz="1.7357E-37"
        izz="0.00013662" />
    </inertial>
    <visual>
      <origin
        xyz="0 0 0"
        rpy="0 0 0" />
      <geometry>
        <mesh
          filename="package://final assembly.SLDASM/meshes/L_Link.STL" />
      </geometry>
      <material
        name="">
        <color
          rgba="1 1 1 1" />
      </material>
    </visual>
    <collision>
      <origin
        xyz="0 0 0"
        rpy="0 0 0" />
      <geometry>
        <mesh
          filename="package://final assembly.SLDASM/meshes/L_Link.STL" />
      </geometry>
    </collision>
  </link>
  <joint
    name="joint_L"
    type="continuous">
    <origin
      xyz="-0.19418 -0.5675 -0.16331"
      rpy="1.5708 0 0" />
    <parent
      link="base_link" />
    <child
      link="L_Link" />
    <axis
      xyz="0 0 0" />
  </joint>
  <link
    name="R_Link">
    <inertial>
      <origin
        xyz="0 0 0"
        rpy="0 0 0" />
      <mass
        value="0.18269" />
      <inertia
        ixx="0.00025245"
        ixy="-5.5928E-22"
        ixz="1.0751E-21"
        iyy="0.00013662"
        iyz="0"
        izz="0.00013662" />
    </inertial>
    <visual>
      <origin
        xyz="0 0 0"
        rpy="0 0 0" />
      <geometry>
        <mesh
          filename="package://final assembly.SLDASM/meshes/R_Link.STL" />
      </geometry>
      <material
        name="">
        <color
          rgba="1 1 1 1" />
      </material>
    </visual>
    <collision>
      <origin
        xyz="0 0 0"
        rpy="0 0 0" />
      <geometry>
        <mesh
          filename="package://final assembly.SLDASM/meshes/R_Link.STL" />
      </geometry>
    </collision>
  </link>
  <joint
    name="joint_R"
    type="continuous">
    <origin
      xyz="0.19582 -0.5675 -0.16331"
      rpy="2.8263 0 3.1416" />
    <parent
      link="base_link" />
    <child
      link="R_Link" />
    <axis
      xyz="0 0 0" />
  </joint>
</robot>